[Errno 2] No such file or directory: '/home/LAB/changc/etbert/datasets/cross_platform/etbert/testdataset/'
Dataset directory /home/LAB/changc/etbert/datasets/cross_platform/etbert/testdataset/ not exist.
Begin to obtain new dataset.
label_name_list ['b612kaji']
session_pcap_path {'b612kaji': '/home/LAB/changc/etbert/datasets/cross_platform/etbert/pcapb612kaji'}

Begin to generate features.
  0%|          | 0/1 [00:00<?, ?it/s]100%|██████████| 1/1 [00:00<00:00, 2557.50it/s]
label_id dict_items([('b612kaji', 0)])
dataset dict_items([(0, {'samples': 0, 'payload': {}, 'length': {}, 'time': {}, 'direction': {}, 'message_type': {}})])
0	b612kaji	0
all	0
category flow
0	0
1	0
2	0
3	0
4	0
5	0
6	0
7	0
8	0
9	0
10	0
11	0
12	0
13	0
14	0
15	0
16	0
17	0
18	0
19	0
20	0
21	0
22	0
23	0
24	0
25	0
26	0
27	0
28	0
29	0
30	0
31	0
32	0
33	0
34	0
35	0
36	0
37	0
38	0
39	0
40	0
41	0
42	0
43	0
44	0
45	0
46	0
47	0
48	0
49	0
50	0
51	0
52	0
53	0
54	0
55	0
56	0
57	0
58	0
59	0
60	0
61	0
62	0
63	0
64	0
65	0
66	0
67	0
68	0
69	0
70	0
71	0
72	0
73	0
74	0
75	0
76	0
77	0
78	0
79	0
80	0
81	0
82	0
83	0
84	0
85	0
86	0
87	0
88	0
89	0
90	0
91	0
92	0
93	0
94	0
95	0
96	0
97	0
98	0
99	0
100	0
101	0
102	0
103	0
104	0
105	0
106	0
107	0
108	0
109	0
110	0
111	0
112	0
113	0
114	0
115	0
116	0
117	0
118	0
119	0
all	0
Traceback (most recent call last):
  File "/home/LAB/changc/etbert/data_process/main.py", line 342, in <module>
    main()
  File "/home/LAB/changc/.conda/envs/ET-BERT/lib/python3.9/site-packages/click/core.py", line 1157, in __call__
    return self.main(*args, **kwargs)
  File "/home/LAB/changc/.conda/envs/ET-BERT/lib/python3.9/site-packages/click/core.py", line 1078, in main
    rv = self.invoke(ctx)
  File "/home/LAB/changc/.conda/envs/ET-BERT/lib/python3.9/site-packages/click/core.py", line 1434, in invoke
    return ctx.invoke(self.callback, **ctx.params)
  File "/home/LAB/changc/.conda/envs/ET-BERT/lib/python3.9/site-packages/click/core.py", line 783, in invoke
    return __callback(*args, **kwargs)
  File "/home/LAB/changc/etbert/data_process/main.py", line 339, in main
    dataset_extract(train_model)
  File "/home/LAB/changc/etbert/data_process/main.py", line 134, in dataset_extract
    for train_index, test_index in split_1.split(x_payload, dataset_label):
  File "/home/LAB/changc/.conda/envs/ET-BERT/lib/python3.9/site-packages/sklearn/model_selection/_split.py", line 2332, in split
    y = check_array(y, input_name="y", ensure_2d=False, dtype=None)
  File "/home/LAB/changc/.conda/envs/ET-BERT/lib/python3.9/site-packages/sklearn/utils/validation.py", line 1082, in check_array
    raise ValueError(
ValueError: Found array with 0 sample(s) (shape=(0,)) while a minimum of 1 is required.
